WARNING 2025-07-05 07:46:27,235 log 39271 128781045956736 Not Found: /api/services/service-requests/1/approve_request/
ERROR 2025-07-05 07:46:39,558 log 39271 128781045956736 Internal Server Error: /api/services/clients/
Traceback (most recent call last):
  File "/home/abdo/ITI/Ageri/venv/lib/python3.12/site-packages/django/core/handlers/exception.py", line 55, in inner
    response = get_response(request)
               ^^^^^^^^^^^^^^^^^^^^^
  File "/home/abdo/ITI/Ageri/venv/lib/python3.12/site-packages/django/core/handlers/base.py", line 192, in _get_response
    wrapped_callback = self.make_view_atomic(callback)
                       ^^^^^^^^^^^^^^^^^^^^^^^^^^^^^^^
  File "/home/abdo/ITI/Ageri/venv/lib/python3.12/site-packages/django/core/handlers/base.py", line 348, in make_view_atomic
    if settings_dict["ATOMIC_REQUESTS"] and alias not in non_atomic_requests:
       ~~~~~~~~~~~~~^^^^^^^^^^^^^^^^^^^
KeyError: 'ATOMIC_REQUESTS'
WARNING 2025-07-05 07:46:45,278 log 39271 128781045956736 Not Found: /api/services/service-requests/1/complete_request/
ERROR 2025-07-05 07:46:52,300 log 39271 128781045956736 Internal Server Error: /api/services/test-services/
Traceback (most recent call last):
  File "/home/abdo/ITI/Ageri/venv/lib/python3.12/site-packages/django/core/handlers/exception.py", line 55, in inner
    response = get_response(request)
               ^^^^^^^^^^^^^^^^^^^^^
  File "/home/abdo/ITI/Ageri/venv/lib/python3.12/site-packages/django/core/handlers/base.py", line 192, in _get_response
    wrapped_callback = self.make_view_atomic(callback)
                       ^^^^^^^^^^^^^^^^^^^^^^^^^^^^^^^
  File "/home/abdo/ITI/Ageri/venv/lib/python3.12/site-packages/django/core/handlers/base.py", line 348, in make_view_atomic
    if settings_dict["ATOMIC_REQUESTS"] and alias not in non_atomic_requests:
       ~~~~~~~~~~~~~^^^^^^^^^^^^^^^^^^^
KeyError: 'ATOMIC_REQUESTS'
ERROR 2025-07-05 07:46:58,989 log 39271 128781045956736 Internal Server Error: /api/services/test-services/
Traceback (most recent call last):
  File "/home/abdo/ITI/Ageri/venv/lib/python3.12/site-packages/django/core/handlers/exception.py", line 55, in inner
    response = get_response(request)
               ^^^^^^^^^^^^^^^^^^^^^
  File "/home/abdo/ITI/Ageri/venv/lib/python3.12/site-packages/django/core/handlers/base.py", line 192, in _get_response
    wrapped_callback = self.make_view_atomic(callback)
                       ^^^^^^^^^^^^^^^^^^^^^^^^^^^^^^^
  File "/home/abdo/ITI/Ageri/venv/lib/python3.12/site-packages/django/core/handlers/base.py", line 348, in make_view_atomic
    if settings_dict["ATOMIC_REQUESTS"] and alias not in non_atomic_requests:
       ~~~~~~~~~~~~~^^^^^^^^^^^^^^^^^^^
KeyError: 'ATOMIC_REQUESTS'
WARNING 2025-07-05 07:47:04,287 log 39271 128781045956736 Not Found: /api/services/service-requests/
WARNING 2025-07-05 07:47:09,750 log 39271 128781045956736 Not Found: /api/services/service-requests/
WARNING 2025-07-05 07:47:21,820 log 39271 128781045956736 Not Found: /api/services/service-requests/1/start_request/
ERROR 2025-07-05 07:47:28,386 log 39271 128781045956736 Internal Server Error: /api/services/test-services/
Traceback (most recent call last):
  File "/home/abdo/ITI/Ageri/venv/lib/python3.12/site-packages/django/core/handlers/exception.py", line 55, in inner
    response = get_response(request)
               ^^^^^^^^^^^^^^^^^^^^^
  File "/home/abdo/ITI/Ageri/venv/lib/python3.12/site-packages/django/core/handlers/base.py", line 192, in _get_response
    wrapped_callback = self.make_view_atomic(callback)
                       ^^^^^^^^^^^^^^^^^^^^^^^^^^^^^^^
  File "/home/abdo/ITI/Ageri/venv/lib/python3.12/site-packages/django/core/handlers/base.py", line 348, in make_view_atomic
    if settings_dict["ATOMIC_REQUESTS"] and alias not in non_atomic_requests:
       ~~~~~~~~~~~~~^^^^^^^^^^^^^^^^^^^
KeyError: 'ATOMIC_REQUESTS'
ERROR 2025-07-05 07:47:35,325 log 39271 128781045956736 Internal Server Error: /api/services/test-services/
Traceback (most recent call last):
  File "/home/abdo/ITI/Ageri/venv/lib/python3.12/site-packages/django/core/handlers/exception.py", line 55, in inner
    response = get_response(request)
               ^^^^^^^^^^^^^^^^^^^^^
  File "/home/abdo/ITI/Ageri/venv/lib/python3.12/site-packages/django/core/handlers/base.py", line 192, in _get_response
    wrapped_callback = self.make_view_atomic(callback)
                       ^^^^^^^^^^^^^^^^^^^^^^^^^^^^^^^
  File "/home/abdo/ITI/Ageri/venv/lib/python3.12/site-packages/django/core/handlers/base.py", line 348, in make_view_atomic
    if settings_dict["ATOMIC_REQUESTS"] and alias not in non_atomic_requests:
       ~~~~~~~~~~~~~^^^^^^^^^^^^^^^^^^^
KeyError: 'ATOMIC_REQUESTS'
ERROR 2025-07-05 08:37:47,504 log 25153 126980623450240 Internal Server Error: /api/services/requests/1/approve_request/
Traceback (most recent call last):
  File "/home/abdo/ITI/Ageri/venv/lib/python3.12/site-packages/django/core/handlers/exception.py", line 55, in inner
    response = get_response(request)
               ^^^^^^^^^^^^^^^^^^^^^
  File "/home/abdo/ITI/Ageri/venv/lib/python3.12/site-packages/django/core/handlers/base.py", line 192, in _get_response
    wrapped_callback = self.make_view_atomic(callback)
                       ^^^^^^^^^^^^^^^^^^^^^^^^^^^^^^^
  File "/home/abdo/ITI/Ageri/venv/lib/python3.12/site-packages/django/core/handlers/base.py", line 348, in make_view_atomic
    if settings_dict["ATOMIC_REQUESTS"] and alias not in non_atomic_requests:
       ~~~~~~~~~~~~~^^^^^^^^^^^^^^^^^^^
KeyError: 'ATOMIC_REQUESTS'
ERROR 2025-07-05 08:37:52,655 log 25153 126980623450240 Internal Server Error: /api/services/requests/1/assign_technician/
Traceback (most recent call last):
  File "/home/abdo/ITI/Ageri/venv/lib/python3.12/site-packages/django/core/handlers/exception.py", line 55, in inner
    response = get_response(request)
               ^^^^^^^^^^^^^^^^^^^^^
  File "/home/abdo/ITI/Ageri/venv/lib/python3.12/site-packages/django/core/handlers/base.py", line 192, in _get_response
    wrapped_callback = self.make_view_atomic(callback)
                       ^^^^^^^^^^^^^^^^^^^^^^^^^^^^^^^
  File "/home/abdo/ITI/Ageri/venv/lib/python3.12/site-packages/django/core/handlers/base.py", line 348, in make_view_atomic
    if settings_dict["ATOMIC_REQUESTS"] and alias not in non_atomic_requests:
       ~~~~~~~~~~~~~^^^^^^^^^^^^^^^^^^^
KeyError: 'ATOMIC_REQUESTS'
ERROR 2025-07-05 08:37:58,213 log 25153 126980623450240 Internal Server Error: /api/services/clients/
Traceback (most recent call last):
  File "/home/abdo/ITI/Ageri/venv/lib/python3.12/site-packages/django/core/handlers/exception.py", line 55, in inner
    response = get_response(request)
               ^^^^^^^^^^^^^^^^^^^^^
  File "/home/abdo/ITI/Ageri/venv/lib/python3.12/site-packages/django/core/handlers/base.py", line 192, in _get_response
    wrapped_callback = self.make_view_atomic(callback)
                       ^^^^^^^^^^^^^^^^^^^^^^^^^^^^^^^
  File "/home/abdo/ITI/Ageri/venv/lib/python3.12/site-packages/django/core/handlers/base.py", line 348, in make_view_atomic
    if settings_dict["ATOMIC_REQUESTS"] and alias not in non_atomic_requests:
       ~~~~~~~~~~~~~^^^^^^^^^^^^^^^^^^^
KeyError: 'ATOMIC_REQUESTS'
ERROR 2025-07-05 08:38:03,536 log 25153 126980623450240 Internal Server Error: /api/services/requests/1/complete_request/
Traceback (most recent call last):
  File "/home/abdo/ITI/Ageri/venv/lib/python3.12/site-packages/django/core/handlers/exception.py", line 55, in inner
    response = get_response(request)
               ^^^^^^^^^^^^^^^^^^^^^
  File "/home/abdo/ITI/Ageri/venv/lib/python3.12/site-packages/django/core/handlers/base.py", line 192, in _get_response
    wrapped_callback = self.make_view_atomic(callback)
                       ^^^^^^^^^^^^^^^^^^^^^^^^^^^^^^^
  File "/home/abdo/ITI/Ageri/venv/lib/python3.12/site-packages/django/core/handlers/base.py", line 348, in make_view_atomic
    if settings_dict["ATOMIC_REQUESTS"] and alias not in non_atomic_requests:
       ~~~~~~~~~~~~~^^^^^^^^^^^^^^^^^^^
KeyError: 'ATOMIC_REQUESTS'
ERROR 2025-07-05 08:38:08,617 log 25153 126980623450240 Internal Server Error: /api/services/test-services/
Traceback (most recent call last):
  File "/home/abdo/ITI/Ageri/venv/lib/python3.12/site-packages/django/core/handlers/exception.py", line 55, in inner
    response = get_response(request)
               ^^^^^^^^^^^^^^^^^^^^^
  File "/home/abdo/ITI/Ageri/venv/lib/python3.12/site-packages/django/core/handlers/base.py", line 192, in _get_response
    wrapped_callback = self.make_view_atomic(callback)
                       ^^^^^^^^^^^^^^^^^^^^^^^^^^^^^^^
  File "/home/abdo/ITI/Ageri/venv/lib/python3.12/site-packages/django/core/handlers/base.py", line 348, in make_view_atomic
    if settings_dict["ATOMIC_REQUESTS"] and alias not in non_atomic_requests:
       ~~~~~~~~~~~~~^^^^^^^^^^^^^^^^^^^
KeyError: 'ATOMIC_REQUESTS'
ERROR 2025-07-05 08:38:14,327 log 25153 126980623450240 Internal Server Error: /api/services/test-services/
Traceback (most recent call last):
  File "/home/abdo/ITI/Ageri/venv/lib/python3.12/site-packages/django/core/handlers/exception.py", line 55, in inner
    response = get_response(request)
               ^^^^^^^^^^^^^^^^^^^^^
  File "/home/abdo/ITI/Ageri/venv/lib/python3.12/site-packages/django/core/handlers/base.py", line 192, in _get_response
    wrapped_callback = self.make_view_atomic(callback)
                       ^^^^^^^^^^^^^^^^^^^^^^^^^^^^^^^
  File "/home/abdo/ITI/Ageri/venv/lib/python3.12/site-packages/django/core/handlers/base.py", line 348, in make_view_atomic
    if settings_dict["ATOMIC_REQUESTS"] and alias not in non_atomic_requests:
       ~~~~~~~~~~~~~^^^^^^^^^^^^^^^^^^^
KeyError: 'ATOMIC_REQUESTS'
ERROR 2025-07-05 08:38:19,808 log 25153 126980623450240 Internal Server Error: /api/services/requests/
Traceback (most recent call last):
  File "/home/abdo/ITI/Ageri/venv/lib/python3.12/site-packages/django/core/handlers/exception.py", line 55, in inner
    response = get_response(request)
               ^^^^^^^^^^^^^^^^^^^^^
  File "/home/abdo/ITI/Ageri/venv/lib/python3.12/site-packages/django/core/handlers/base.py", line 192, in _get_response
    wrapped_callback = self.make_view_atomic(callback)
                       ^^^^^^^^^^^^^^^^^^^^^^^^^^^^^^^
  File "/home/abdo/ITI/Ageri/venv/lib/python3.12/site-packages/django/core/handlers/base.py", line 348, in make_view_atomic
    if settings_dict["ATOMIC_REQUESTS"] and alias not in non_atomic_requests:
       ~~~~~~~~~~~~~^^^^^^^^^^^^^^^^^^^
KeyError: 'ATOMIC_REQUESTS'
ERROR 2025-07-05 08:38:25,030 log 25153 126980623450240 Internal Server Error: /api/services/requests/
Traceback (most recent call last):
  File "/home/abdo/ITI/Ageri/venv/lib/python3.12/site-packages/django/core/handlers/exception.py", line 55, in inner
    response = get_response(request)
               ^^^^^^^^^^^^^^^^^^^^^
  File "/home/abdo/ITI/Ageri/venv/lib/python3.12/site-packages/django/core/handlers/base.py", line 192, in _get_response
    wrapped_callback = self.make_view_atomic(callback)
                       ^^^^^^^^^^^^^^^^^^^^^^^^^^^^^^^
  File "/home/abdo/ITI/Ageri/venv/lib/python3.12/site-packages/django/core/handlers/base.py", line 348, in make_view_atomic
    if settings_dict["ATOMIC_REQUESTS"] and alias not in non_atomic_requests:
       ~~~~~~~~~~~~~^^^^^^^^^^^^^^^^^^^
KeyError: 'ATOMIC_REQUESTS'
ERROR 2025-07-05 08:38:30,309 log 25153 126980623450240 Internal Server Error: /api/services/test-services/statistics/
Traceback (most recent call last):
  File "/home/abdo/ITI/Ageri/venv/lib/python3.12/site-packages/django/core/handlers/exception.py", line 55, in inner
    response = get_response(request)
               ^^^^^^^^^^^^^^^^^^^^^
  File "/home/abdo/ITI/Ageri/venv/lib/python3.12/site-packages/django/core/handlers/base.py", line 192, in _get_response
    wrapped_callback = self.make_view_atomic(callback)
                       ^^^^^^^^^^^^^^^^^^^^^^^^^^^^^^^
  File "/home/abdo/ITI/Ageri/venv/lib/python3.12/site-packages/django/core/handlers/base.py", line 348, in make_view_atomic
    if settings_dict["ATOMIC_REQUESTS"] and alias not in non_atomic_requests:
       ~~~~~~~~~~~~~^^^^^^^^^^^^^^^^^^^
KeyError: 'ATOMIC_REQUESTS'
ERROR 2025-07-05 08:38:35,829 log 25153 126980623450240 Internal Server Error: /api/services/requests/1/start_request/
Traceback (most recent call last):
  File "/home/abdo/ITI/Ageri/venv/lib/python3.12/site-packages/django/core/handlers/exception.py", line 55, in inner
    response = get_response(request)
               ^^^^^^^^^^^^^^^^^^^^^
  File "/home/abdo/ITI/Ageri/venv/lib/python3.12/site-packages/django/core/handlers/base.py", line 192, in _get_response
    wrapped_callback = self.make_view_atomic(callback)
                       ^^^^^^^^^^^^^^^^^^^^^^^^^^^^^^^
  File "/home/abdo/ITI/Ageri/venv/lib/python3.12/site-packages/django/core/handlers/base.py", line 348, in make_view_atomic
    if settings_dict["ATOMIC_REQUESTS"] and alias not in non_atomic_requests:
       ~~~~~~~~~~~~~^^^^^^^^^^^^^^^^^^^
KeyError: 'ATOMIC_REQUESTS'
ERROR 2025-07-05 08:38:41,210 log 25153 126980623450240 Internal Server Error: /api/services/test-services/
Traceback (most recent call last):
  File "/home/abdo/ITI/Ageri/venv/lib/python3.12/site-packages/django/core/handlers/exception.py", line 55, in inner
    response = get_response(request)
               ^^^^^^^^^^^^^^^^^^^^^
  File "/home/abdo/ITI/Ageri/venv/lib/python3.12/site-packages/django/core/handlers/base.py", line 192, in _get_response
    wrapped_callback = self.make_view_atomic(callback)
                       ^^^^^^^^^^^^^^^^^^^^^^^^^^^^^^^
  File "/home/abdo/ITI/Ageri/venv/lib/python3.12/site-packages/django/core/handlers/base.py", line 348, in make_view_atomic
    if settings_dict["ATOMIC_REQUESTS"] and alias not in non_atomic_requests:
       ~~~~~~~~~~~~~^^^^^^^^^^^^^^^^^^^
KeyError: 'ATOMIC_REQUESTS'
ERROR 2025-07-05 08:38:46,656 log 25153 126980623450240 Internal Server Error: /api/services/test-services/
Traceback (most recent call last):
  File "/home/abdo/ITI/Ageri/venv/lib/python3.12/site-packages/django/core/handlers/exception.py", line 55, in inner
    response = get_response(request)
               ^^^^^^^^^^^^^^^^^^^^^
  File "/home/abdo/ITI/Ageri/venv/lib/python3.12/site-packages/django/core/handlers/base.py", line 192, in _get_response
    wrapped_callback = self.make_view_atomic(callback)
                       ^^^^^^^^^^^^^^^^^^^^^^^^^^^^^^^
  File "/home/abdo/ITI/Ageri/venv/lib/python3.12/site-packages/django/core/handlers/base.py", line 348, in make_view_atomic
    if settings_dict["ATOMIC_REQUESTS"] and alias not in non_atomic_requests:
       ~~~~~~~~~~~~~^^^^^^^^^^^^^^^^^^^
KeyError: 'ATOMIC_REQUESTS'
ERROR 2025-07-05 09:39:27,113 log 34846 127349621153920 Internal Server Error: /api/services/test-services/
Traceback (most recent call last):
  File "/home/abdo/ITI/Ageri/venv/lib/python3.12/site-packages/django/core/handlers/exception.py", line 55, in inner
    response = get_response(request)
               ^^^^^^^^^^^^^^^^^^^^^
  File "/home/abdo/ITI/Ageri/venv/lib/python3.12/site-packages/django/core/handlers/base.py", line 192, in _get_response
    wrapped_callback = self.make_view_atomic(callback)
                       ^^^^^^^^^^^^^^^^^^^^^^^^^^^^^^^
  File "/home/abdo/ITI/Ageri/venv/lib/python3.12/site-packages/django/core/handlers/base.py", line 348, in make_view_atomic
    if settings_dict["ATOMIC_REQUESTS"] and alias not in non_atomic_requests:
       ~~~~~~~~~~~~~^^^^^^^^^^^^^^^^^^^
KeyError: 'ATOMIC_REQUESTS'
WARNING 2025-07-08 11:53:50,855 log 17892 130925053091968 Forbidden: /api/training/api/courses/
WARNING 2025-07-08 11:53:54,062 log 17892 130925053091968 Unauthorized: /api/training/api/courses/
WARNING 2025-07-08 11:53:54,818 log 17892 130925053091968 Bad Request: /api/training/api/courses/1/enroll/
ERROR 2025-07-08 12:08:52,721 log 22286 126213029699712 Internal Server Error: /api/auth/users/me/
Traceback (most recent call last):
  File "/home/abdo/ITI/Ageri/venv/lib/python3.12/site-packages/django/core/handlers/exception.py", line 55, in inner
    response = get_response(request)
               ^^^^^^^^^^^^^^^^^^^^^
  File "/home/abdo/ITI/Ageri/venv/lib/python3.12/site-packages/django/core/handlers/base.py", line 197, in _get_response
    response = wrapped_callback(request, *callback_args, **callback_kwargs)
               ^^^^^^^^^^^^^^^^^^^^^^^^^^^^^^^^^^^^^^^^^^^^^^^^^^^^^^^^^^^^
  File "/home/abdo/ITI/Ageri/venv/lib/python3.12/site-packages/django/views/decorators/csrf.py", line 56, in wrapper_view
    return view_func(*args, **kwargs)
           ^^^^^^^^^^^^^^^^^^^^^^^^^^
  File "/home/abdo/ITI/Ageri/venv/lib/python3.12/site-packages/django/views/generic/base.py", line 104, in view
    return self.dispatch(request, *args, **kwargs)
           ^^^^^^^^^^^^^^^^^^^^^^^^^^^^^^^^^^^^^^^
  File "/home/abdo/ITI/Ageri/venv/lib/python3.12/site-packages/rest_framework/views.py", line 509, in dispatch
    response = self.handle_exception(exc)
               ^^^^^^^^^^^^^^^^^^^^^^^^^^
  File "/home/abdo/ITI/Ageri/venv/lib/python3.12/site-packages/rest_framework/views.py", line 469, in handle_exception
    self.raise_uncaught_exception(exc)
  File "/home/abdo/ITI/Ageri/venv/lib/python3.12/site-packages/rest_framework/views.py", line 480, in raise_uncaught_exception
    raise exc
  File "/home/abdo/ITI/Ageri/venv/lib/python3.12/site-packages/rest_framework/views.py", line 506, in dispatch
    response = handler(request, *args, **kwargs)
               ^^^^^^^^^^^^^^^^^^^^^^^^^^^^^^^^^
  File "/home/abdo/ITI/Ageri/venv/lib/python3.12/site-packages/rest_framework/generics.py", line 252, in get
    return self.retrieve(request, *args, **kwargs)
           ^^^^^^^^^^^^^^^^^^^^^^^^^^^^^^^^^^^^^^^
  File "/home/abdo/ITI/Ageri/venv/lib/python3.12/site-packages/rest_framework/mixins.py", line 54, in retrieve
    instance = self.get_object()
               ^^^^^^^^^^^^^^^^^
  File "/home/abdo/ITI/Ageri/accounts/views.py", line 84, in get_object
    return super().get_object()
           ^^^^^^^^^^^^^^^^^^^^
  File "/home/abdo/ITI/Ageri/venv/lib/python3.12/site-packages/rest_framework/generics.py", line 88, in get_object
    assert lookup_url_kwarg in self.kwargs, (
           ^^^^^^^^^^^^^^^^^^^^^^^^^^^^^^^
AssertionError: Expected view UserDetailView to be called with a URL keyword argument named "pk". Fix your URL conf, or set the `.lookup_field` attribute on the view correctly.
WARNING 2025-07-08 12:08:53,643 log 22286 126213029699712 Not Found: /api/auth/logout/
ERROR 2025-07-08 12:08:55,432 log 22286 126213029699712 Internal Server Error: /api/auth/users/me/
Traceback (most recent call last):
  File "/home/abdo/ITI/Ageri/venv/lib/python3.12/site-packages/django/core/handlers/exception.py", line 55, in inner
    response = get_response(request)
               ^^^^^^^^^^^^^^^^^^^^^
  File "/home/abdo/ITI/Ageri/venv/lib/python3.12/site-packages/django/core/handlers/base.py", line 197, in _get_response
    response = wrapped_callback(request, *callback_args, **callback_kwargs)
               ^^^^^^^^^^^^^^^^^^^^^^^^^^^^^^^^^^^^^^^^^^^^^^^^^^^^^^^^^^^^
  File "/home/abdo/ITI/Ageri/venv/lib/python3.12/site-packages/django/views/decorators/csrf.py", line 56, in wrapper_view
    return view_func(*args, **kwargs)
           ^^^^^^^^^^^^^^^^^^^^^^^^^^
  File "/home/abdo/ITI/Ageri/venv/lib/python3.12/site-packages/django/views/generic/base.py", line 104, in view
    return self.dispatch(request, *args, **kwargs)
           ^^^^^^^^^^^^^^^^^^^^^^^^^^^^^^^^^^^^^^^
  File "/home/abdo/ITI/Ageri/venv/lib/python3.12/site-packages/rest_framework/views.py", line 509, in dispatch
    response = self.handle_exception(exc)
               ^^^^^^^^^^^^^^^^^^^^^^^^^^
  File "/home/abdo/ITI/Ageri/venv/lib/python3.12/site-packages/rest_framework/views.py", line 469, in handle_exception
    self.raise_uncaught_exception(exc)
  File "/home/abdo/ITI/Ageri/venv/lib/python3.12/site-packages/rest_framework/views.py", line 480, in raise_uncaught_exception
    raise exc
  File "/home/abdo/ITI/Ageri/venv/lib/python3.12/site-packages/rest_framework/views.py", line 506, in dispatch
    response = handler(request, *args, **kwargs)
               ^^^^^^^^^^^^^^^^^^^^^^^^^^^^^^^^^
  File "/home/abdo/ITI/Ageri/venv/lib/python3.12/site-packages/rest_framework/generics.py", line 255, in put
    return self.update(request, *args, **kwargs)
           ^^^^^^^^^^^^^^^^^^^^^^^^^^^^^^^^^^^^^
  File "/home/abdo/ITI/Ageri/venv/lib/python3.12/site-packages/rest_framework/mixins.py", line 65, in update
    instance = self.get_object()
               ^^^^^^^^^^^^^^^^^
  File "/home/abdo/ITI/Ageri/accounts/views.py", line 84, in get_object
    return super().get_object()
           ^^^^^^^^^^^^^^^^^^^^
  File "/home/abdo/ITI/Ageri/venv/lib/python3.12/site-packages/rest_framework/generics.py", line 88, in get_object
    assert lookup_url_kwarg in self.kwargs, (
           ^^^^^^^^^^^^^^^^^^^^^^^^^^^^^^^
AssertionError: Expected view UserDetailView to be called with a URL keyword argument named "pk". Fix your URL conf, or set the `.lookup_field` attribute on the view correctly.
WARNING 2025-07-08 12:08:56,713 log 22286 126213029699712 Forbidden: /api/auth/users/3/approve/
WARNING 2025-07-08 12:08:56,714 log 22286 126213029699712 Method Not Allowed: /api/auth/users/3/approve/
WARNING 2025-07-08 12:08:59,252 log 22286 126213029699712 Bad Request: /api/auth/login/
WARNING 2025-07-08 12:09:01,107 log 22286 126213029699712 Bad Request: /api/auth/login/
WARNING 2025-07-08 12:09:02,010 log 22286 126213029699712 Bad Request: /api/auth/register/
WARNING 2025-07-08 12:09:03,407 log 22286 126213029699712 Bad Request: /api/auth/register/
WARNING 2025-07-08 12:09:04,794 log 22286 126213029699712 Forbidden: /api/auth/users/
WARNING 2025-07-08 12:09:22,814 log 22286 126213029699712 Forbidden: /api/services/requests/1/approve_request/
WARNING 2025-07-08 12:09:24,118 log 22286 126213029699712 Bad Request: /api/services/requests/1/assign_technician/
WARNING 2025-07-08 12:09:25,396 log 22286 126213029699712 Forbidden: /api/services/clients/
WARNING 2025-07-08 12:09:27,978 log 22286 126213029699712 Bad Request: /api/services/test-services/
WARNING 2025-07-08 12:09:29,240 log 22286 126213029699712 Forbidden: /api/services/test-services/
WARNING 2025-07-08 12:09:30,541 log 22286 126213029699712 Bad Request: /api/services/requests/
ERROR 2025-07-08 12:09:33,071 log 22286 126213029699712 Internal Server Error: /api/services/test-services/statistics/
Traceback (most recent call last):
  File "/home/abdo/ITI/Ageri/venv/lib/python3.12/site-packages/django/core/handlers/exception.py", line 55, in inner
    response = get_response(request)
               ^^^^^^^^^^^^^^^^^^^^^
  File "/home/abdo/ITI/Ageri/venv/lib/python3.12/site-packages/django/core/handlers/base.py", line 197, in _get_response
    response = wrapped_callback(request, *callback_args, **callback_kwargs)
               ^^^^^^^^^^^^^^^^^^^^^^^^^^^^^^^^^^^^^^^^^^^^^^^^^^^^^^^^^^^^
  File "/home/abdo/ITI/Ageri/venv/lib/python3.12/site-packages/django/views/decorators/csrf.py", line 56, in wrapper_view
    return view_func(*args, **kwargs)
           ^^^^^^^^^^^^^^^^^^^^^^^^^^
  File "/home/abdo/ITI/Ageri/venv/lib/python3.12/site-packages/rest_framework/viewsets.py", line 125, in view
    return self.dispatch(request, *args, **kwargs)
           ^^^^^^^^^^^^^^^^^^^^^^^^^^^^^^^^^^^^^^^
  File "/home/abdo/ITI/Ageri/venv/lib/python3.12/site-packages/rest_framework/views.py", line 509, in dispatch
    response = self.handle_exception(exc)
               ^^^^^^^^^^^^^^^^^^^^^^^^^^
  File "/home/abdo/ITI/Ageri/venv/lib/python3.12/site-packages/rest_framework/views.py", line 469, in handle_exception
    self.raise_uncaught_exception(exc)
  File "/home/abdo/ITI/Ageri/venv/lib/python3.12/site-packages/rest_framework/views.py", line 480, in raise_uncaught_exception
    raise exc
  File "/home/abdo/ITI/Ageri/venv/lib/python3.12/site-packages/rest_framework/views.py", line 506, in dispatch
    response = handler(request, *args, **kwargs)
               ^^^^^^^^^^^^^^^^^^^^^^^^^^^^^^^^^
  File "/home/abdo/ITI/Ageri/services/views.py", line 125, in statistics
    'current_usage': queryset.aggregate(current=Sum('current_requests'))['current'] or 0,
                     ^^^^^^^^^^^^^^^^^^^^^^^^^^^^^^^^^^^^^^^^^^^^^^^^^^^
  File "/home/abdo/ITI/Ageri/venv/lib/python3.12/site-packages/django/db/models/query.py", line 592, in aggregate
    return self.query.chain().get_aggregation(self.db, kwargs)
           ^^^^^^^^^^^^^^^^^^^^^^^^^^^^^^^^^^^^^^^^^^^^^^^^^^^
  File "/home/abdo/ITI/Ageri/venv/lib/python3.12/site-packages/django/db/models/sql/query.py", line 398, in get_aggregation
    aggregate = aggregate_expr.resolve_expression(
                ^^^^^^^^^^^^^^^^^^^^^^^^^^^^^^^^^^
  File "/home/abdo/ITI/Ageri/venv/lib/python3.12/site-packages/django/db/models/aggregates.py", line 64, in resolve_expression
    c = super().resolve_expression(query, allow_joins, reuse, summarize)
        ^^^^^^^^^^^^^^^^^^^^^^^^^^^^^^^^^^^^^^^^^^^^^^^^^^^^^^^^^^^^^^^^
  File "/home/abdo/ITI/Ageri/venv/lib/python3.12/site-packages/django/db/models/expressions.py", line 950, in resolve_expression
    c.source_expressions[pos] = arg.resolve_expression(
                                ^^^^^^^^^^^^^^^^^^^^^^^
  File "/home/abdo/ITI/Ageri/venv/lib/python3.12/site-packages/django/db/models/expressions.py", line 829, in resolve_expression
    return query.resolve_ref(self.name, allow_joins, reuse, summarize)
           ^^^^^^^^^^^^^^^^^^^^^^^^^^^^^^^^^^^^^^^^^^^^^^^^^^^^^^^^^^^
  File "/home/abdo/ITI/Ageri/venv/lib/python3.12/site-packages/django/db/models/sql/query.py", line 1976, in resolve_ref
    join_info = self.setup_joins(
                ^^^^^^^^^^^^^^^^^
  File "/home/abdo/ITI/Ageri/venv/lib/python3.12/site-packages/django/db/models/sql/query.py", line 1823, in setup_joins
    path, final_field, targets, rest = self.names_to_path(
                                       ^^^^^^^^^^^^^^^^^^^
  File "/home/abdo/ITI/Ageri/venv/lib/python3.12/site-packages/django/db/models/sql/query.py", line 1724, in names_to_path
    raise FieldError(
django.core.exceptions.FieldError: Cannot resolve keyword 'current_requests' into field. Choices are: base_price, category, contact_email, contact_phone, created_at, department, department_id, description, equipment_used, estimated_duration, featured_image, id, is_featured, is_free, is_public, lab, lab_id, max_concurrent_requests, methodology, name, pricing_structure, requests, required_documents, safety_requirements, sample_requirements, service_brochure, service_code, short_description, status, tags, technician_assignments, technicians, updated_at
ERROR 2025-07-08 12:09:36,928 log 22286 126213029699712 Internal Server Error: /api/services/test-services/
Traceback (most recent call last):
  File "/home/abdo/ITI/Ageri/venv/lib/python3.12/site-packages/django/core/handlers/exception.py", line 55, in inner
    response = get_response(request)
               ^^^^^^^^^^^^^^^^^^^^^
  File "/home/abdo/ITI/Ageri/venv/lib/python3.12/site-packages/django/core/handlers/base.py", line 197, in _get_response
    response = wrapped_callback(request, *callback_args, **callback_kwargs)
               ^^^^^^^^^^^^^^^^^^^^^^^^^^^^^^^^^^^^^^^^^^^^^^^^^^^^^^^^^^^^
  File "/home/abdo/ITI/Ageri/venv/lib/python3.12/site-packages/django/views/decorators/csrf.py", line 56, in wrapper_view
    return view_func(*args, **kwargs)
           ^^^^^^^^^^^^^^^^^^^^^^^^^^
  File "/home/abdo/ITI/Ageri/venv/lib/python3.12/site-packages/rest_framework/viewsets.py", line 125, in view
    return self.dispatch(request, *args, **kwargs)
           ^^^^^^^^^^^^^^^^^^^^^^^^^^^^^^^^^^^^^^^
  File "/home/abdo/ITI/Ageri/venv/lib/python3.12/site-packages/rest_framework/views.py", line 509, in dispatch
    response = self.handle_exception(exc)
               ^^^^^^^^^^^^^^^^^^^^^^^^^^
  File "/home/abdo/ITI/Ageri/venv/lib/python3.12/site-packages/rest_framework/views.py", line 469, in handle_exception
    self.raise_uncaught_exception(exc)
  File "/home/abdo/ITI/Ageri/venv/lib/python3.12/site-packages/rest_framework/views.py", line 480, in raise_uncaught_exception
    raise exc
  File "/home/abdo/ITI/Ageri/venv/lib/python3.12/site-packages/rest_framework/views.py", line 506, in dispatch
    response = handler(request, *args, **kwargs)
               ^^^^^^^^^^^^^^^^^^^^^^^^^^^^^^^^^
  File "/home/abdo/ITI/Ageri/venv/lib/python3.12/site-packages/rest_framework/mixins.py", line 38, in list
    queryset = self.filter_queryset(self.get_queryset())
                                    ^^^^^^^^^^^^^^^^^^^
  File "/home/abdo/ITI/Ageri/services/views.py", line 49, in get_queryset
    if self.request.user.role == 'researcher':
       ^^^^^^^^^^^^^^^^^^^^^^
AttributeError: 'AnonymousUser' object has no attribute 'role'
WARNING 2025-07-08 12:09:38,628 log 22286 126213029699712 Forbidden: /api/training/api/courses/
WARNING 2025-07-08 12:09:42,003 log 22286 126213029699712 Unauthorized: /api/training/api/courses/
WARNING 2025-07-08 12:09:42,845 log 22286 126213029699712 Bad Request: /api/training/api/courses/1/enroll/
WARNING 2025-07-08 13:03:27,534 log 29164 130948572819584 Bad Request: /api/services/test-services/
WARNING 2025-07-08 13:07:06,142 log 30581 140422247899264 Bad Request: /api/services/test-services/
WARNING 2025-07-08 13:09:57,535 log 31013 131555038400640 Bad Request: /api/auth/users/me/
WARNING 2025-07-08 13:09:58,750 log 31013 131555038400640 Forbidden: /api/auth/users/3/approve/
WARNING 2025-07-08 13:09:58,751 log 31013 131555038400640 Method Not Allowed: /api/auth/users/3/approve/
WARNING 2025-07-08 13:10:01,410 log 31013 131555038400640 Bad Request: /api/auth/login/
WARNING 2025-07-08 13:10:03,203 log 31013 131555038400640 Bad Request: /api/auth/login/
WARNING 2025-07-08 13:10:04,001 log 31013 131555038400640 Bad Request: /api/auth/register/
WARNING 2025-07-08 13:10:05,242 log 31013 131555038400640 Bad Request: /api/auth/register/
WARNING 2025-07-08 13:10:06,351 log 31013 131555038400640 Forbidden: /api/auth/users/
WARNING 2025-07-08 13:10:25,342 log 31013 131555038400640 Forbidden: /api/organization/departments/
WARNING 2025-07-08 13:10:27,986 log 31013 131555038400640 Unauthorized: /api/organization/departments/
ERROR 2025-07-08 13:10:29,782 log 31013 131555038400640 Internal Server Error: /api/organization/labs/1/
Traceback (most recent call last):
  File "/home/abdo/ITI/Ageri/venv/lib/python3.12/site-packages/django/core/handlers/exception.py", line 55, in inner
    response = get_response(request)
               ^^^^^^^^^^^^^^^^^^^^^
  File "/home/abdo/ITI/Ageri/venv/lib/python3.12/site-packages/django/core/handlers/base.py", line 197, in _get_response
    response = wrapped_callback(request, *callback_args, **callback_kwargs)
               ^^^^^^^^^^^^^^^^^^^^^^^^^^^^^^^^^^^^^^^^^^^^^^^^^^^^^^^^^^^^
  File "/home/abdo/ITI/Ageri/venv/lib/python3.12/site-packages/django/views/decorators/csrf.py", line 56, in wrapper_view
    return view_func(*args, **kwargs)
           ^^^^^^^^^^^^^^^^^^^^^^^^^^
  File "/home/abdo/ITI/Ageri/venv/lib/python3.12/site-packages/django/views/generic/base.py", line 104, in view
    return self.dispatch(request, *args, **kwargs)
           ^^^^^^^^^^^^^^^^^^^^^^^^^^^^^^^^^^^^^^^
  File "/home/abdo/ITI/Ageri/venv/lib/python3.12/site-packages/rest_framework/views.py", line 509, in dispatch
    response = self.handle_exception(exc)
               ^^^^^^^^^^^^^^^^^^^^^^^^^^
  File "/home/abdo/ITI/Ageri/venv/lib/python3.12/site-packages/rest_framework/views.py", line 469, in handle_exception
    self.raise_uncaught_exception(exc)
  File "/home/abdo/ITI/Ageri/venv/lib/python3.12/site-packages/rest_framework/views.py", line 480, in raise_uncaught_exception
    raise exc
  File "/home/abdo/ITI/Ageri/venv/lib/python3.12/site-packages/rest_framework/views.py", line 506, in dispatch
    response = handler(request, *args, **kwargs)
               ^^^^^^^^^^^^^^^^^^^^^^^^^^^^^^^^^
  File "/home/abdo/ITI/Ageri/venv/lib/python3.12/site-packages/rest_framework/generics.py", line 282, in get
    return self.retrieve(request, *args, **kwargs)
           ^^^^^^^^^^^^^^^^^^^^^^^^^^^^^^^^^^^^^^^
  File "/home/abdo/ITI/Ageri/venv/lib/python3.12/site-packages/rest_framework/mixins.py", line 56, in retrieve
    return Response(serializer.data)
                    ^^^^^^^^^^^^^^^
  File "/home/abdo/ITI/Ageri/venv/lib/python3.12/site-packages/rest_framework/serializers.py", line 555, in data
    ret = super().data
          ^^^^^^^^^^^^
  File "/home/abdo/ITI/Ageri/venv/lib/python3.12/site-packages/rest_framework/serializers.py", line 253, in data
    self._data = self.to_representation(self.instance)
                 ^^^^^^^^^^^^^^^^^^^^^^^^^^^^^^^^^^^^^
  File "/home/abdo/ITI/Ageri/venv/lib/python3.12/site-packages/rest_framework/serializers.py", line 509, in to_representation
    attribute = field.get_attribute(instance)
                ^^^^^^^^^^^^^^^^^^^^^^^^^^^^^
  File "/home/abdo/ITI/Ageri/venv/lib/python3.12/site-packages/rest_framework/fields.py", line 446, in get_attribute
    return get_attribute(instance, self.source_attrs)
           ^^^^^^^^^^^^^^^^^^^^^^^^^^^^^^^^^^^^^^^^^^
  File "/home/abdo/ITI/Ageri/venv/lib/python3.12/site-packages/rest_framework/fields.py", line 96, in get_attribute
    instance = getattr(instance, attr)
               ^^^^^^^^^^^^^^^^^^^^^^^
  File "/home/abdo/ITI/Ageri/organization/models.py", line 98, in current_researchers_count
    return self.researchers.filter(status=StatusChoices.ACTIVE).count()
           ^^^^^^^^^^^^^^^^^^^^^^^^^^^^^^^^^^^^^^^^^^^^^^^^^^^^
  File "/home/abdo/ITI/Ageri/venv/lib/python3.12/site-packages/django/db/models/manager.py", line 87, in manager_method
    return getattr(self.get_queryset(), name)(*args, **kwargs)
           ^^^^^^^^^^^^^^^^^^^^^^^^^^^^^^^^^^^^^^^^^^^^^^^^^^^
  File "/home/abdo/ITI/Ageri/venv/lib/python3.12/site-packages/django/db/models/query.py", line 1436, in filter
    return self._filter_or_exclude(False, args, kwargs)
           ^^^^^^^^^^^^^^^^^^^^^^^^^^^^^^^^^^^^^^^^^^^^
  File "/home/abdo/ITI/Ageri/venv/lib/python3.12/site-packages/django/db/models/query.py", line 1454, in _filter_or_exclude
    clone._filter_or_exclude_inplace(negate, args, kwargs)
  File "/home/abdo/ITI/Ageri/venv/lib/python3.12/site-packages/django/db/models/query.py", line 1461, in _filter_or_exclude_inplace
    self._query.add_q(Q(*args, **kwargs))
  File "/home/abdo/ITI/Ageri/venv/lib/python3.12/site-packages/django/db/models/sql/query.py", line 1545, in add_q
    clause, _ = self._add_q(q_object, self.used_aliases)
                ^^^^^^^^^^^^^^^^^^^^^^^^^^^^^^^^^^^^^^^^
  File "/home/abdo/ITI/Ageri/venv/lib/python3.12/site-packages/django/db/models/sql/query.py", line 1576, in _add_q
    child_clause, needed_inner = self.build_filter(
                                 ^^^^^^^^^^^^^^^^^^
  File "/home/abdo/ITI/Ageri/venv/lib/python3.12/site-packages/django/db/models/sql/query.py", line 1426, in build_filter
    lookups, parts, reffed_expression = self.solve_lookup_type(arg, summarize)
                                        ^^^^^^^^^^^^^^^^^^^^^^^^^^^^^^^^^^^^^^
  File "/home/abdo/ITI/Ageri/venv/lib/python3.12/site-packages/django/db/models/sql/query.py", line 1236, in solve_lookup_type
    _, field, _, lookup_parts = self.names_to_path(lookup_splitted, self.get_meta())
                                ^^^^^^^^^^^^^^^^^^^^^^^^^^^^^^^^^^^^^^^^^^^^^^^^^^^^
  File "/home/abdo/ITI/Ageri/venv/lib/python3.12/site-packages/django/db/models/sql/query.py", line 1724, in names_to_path
    raise FieldError(
django.core.exceptions.FieldError: Cannot resolve keyword 'status' into field. Choices are: approval_date, approved_announcements, approved_by, approved_by_id, approved_comments, approved_posts, approved_users, assigned_requests, assigned_service_requests, assigned_services, authored_announcements, authored_posts, comment_likes, comments, coordinated_public_services, corresponding_publications, course_enrollments, date_joined, department, departments, email, first_name, groups, headed_departments, headed_labs, id, institution, is_active, is_approved, is_staff, is_superuser, lab_assignments, labs, last_login, last_name, logentry, made_assignments, password, phone, profile, publication_assignments, publications, reviewed_publications, reviewed_service_requests, reviewed_summer_applications, role, service_assignments, service_requests, submitted_publications, summer_training_applications, supervised_summer_trainings, taught_courses, user_permissions, username
ERROR 2025-07-08 13:10:30,586 log 31013 131555038400640 Internal Server Error: /api/organization/labs/
Traceback (most recent call last):
  File "/home/abdo/ITI/Ageri/venv/lib/python3.12/site-packages/django/core/handlers/exception.py", line 55, in inner
    response = get_response(request)
               ^^^^^^^^^^^^^^^^^^^^^
  File "/home/abdo/ITI/Ageri/venv/lib/python3.12/site-packages/django/core/handlers/base.py", line 197, in _get_response
    response = wrapped_callback(request, *callback_args, **callback_kwargs)
               ^^^^^^^^^^^^^^^^^^^^^^^^^^^^^^^^^^^^^^^^^^^^^^^^^^^^^^^^^^^^
  File "/home/abdo/ITI/Ageri/venv/lib/python3.12/site-packages/django/views/decorators/csrf.py", line 56, in wrapper_view
    return view_func(*args, **kwargs)
           ^^^^^^^^^^^^^^^^^^^^^^^^^^
  File "/home/abdo/ITI/Ageri/venv/lib/python3.12/site-packages/django/views/generic/base.py", line 104, in view
    return self.dispatch(request, *args, **kwargs)
           ^^^^^^^^^^^^^^^^^^^^^^^^^^^^^^^^^^^^^^^
  File "/home/abdo/ITI/Ageri/venv/lib/python3.12/site-packages/rest_framework/views.py", line 509, in dispatch
    response = self.handle_exception(exc)
               ^^^^^^^^^^^^^^^^^^^^^^^^^^
  File "/home/abdo/ITI/Ageri/venv/lib/python3.12/site-packages/rest_framework/views.py", line 469, in handle_exception
    self.raise_uncaught_exception(exc)
  File "/home/abdo/ITI/Ageri/venv/lib/python3.12/site-packages/rest_framework/views.py", line 480, in raise_uncaught_exception
    raise exc
  File "/home/abdo/ITI/Ageri/venv/lib/python3.12/site-packages/rest_framework/views.py", line 506, in dispatch
    response = handler(request, *args, **kwargs)
               ^^^^^^^^^^^^^^^^^^^^^^^^^^^^^^^^^
  File "/home/abdo/ITI/Ageri/venv/lib/python3.12/site-packages/rest_framework/generics.py", line 239, in get
    return self.list(request, *args, **kwargs)
           ^^^^^^^^^^^^^^^^^^^^^^^^^^^^^^^^^^^
  File "/home/abdo/ITI/Ageri/venv/lib/python3.12/site-packages/rest_framework/mixins.py", line 43, in list
    return self.get_paginated_response(serializer.data)
                                       ^^^^^^^^^^^^^^^
  File "/home/abdo/ITI/Ageri/venv/lib/python3.12/site-packages/rest_framework/serializers.py", line 768, in data
    ret = super().data
          ^^^^^^^^^^^^
  File "/home/abdo/ITI/Ageri/venv/lib/python3.12/site-packages/rest_framework/serializers.py", line 253, in data
    self._data = self.to_representation(self.instance)
                 ^^^^^^^^^^^^^^^^^^^^^^^^^^^^^^^^^^^^^
  File "/home/abdo/ITI/Ageri/venv/lib/python3.12/site-packages/rest_framework/serializers.py", line 687, in to_representation
    self.child.to_representation(item) for item in iterable
    ^^^^^^^^^^^^^^^^^^^^^^^^^^^^^^^^^^
  File "/home/abdo/ITI/Ageri/venv/lib/python3.12/site-packages/rest_framework/serializers.py", line 509, in to_representation
    attribute = field.get_attribute(instance)
                ^^^^^^^^^^^^^^^^^^^^^^^^^^^^^
  File "/home/abdo/ITI/Ageri/venv/lib/python3.12/site-packages/rest_framework/fields.py", line 446, in get_attribute
    return get_attribute(instance, self.source_attrs)
           ^^^^^^^^^^^^^^^^^^^^^^^^^^^^^^^^^^^^^^^^^^
  File "/home/abdo/ITI/Ageri/venv/lib/python3.12/site-packages/rest_framework/fields.py", line 96, in get_attribute
    instance = getattr(instance, attr)
               ^^^^^^^^^^^^^^^^^^^^^^^
  File "/home/abdo/ITI/Ageri/organization/models.py", line 98, in current_researchers_count
    return self.researchers.filter(status=StatusChoices.ACTIVE).count()
           ^^^^^^^^^^^^^^^^^^^^^^^^^^^^^^^^^^^^^^^^^^^^^^^^^^^^
  File "/home/abdo/ITI/Ageri/venv/lib/python3.12/site-packages/django/db/models/manager.py", line 87, in manager_method
    return getattr(self.get_queryset(), name)(*args, **kwargs)
           ^^^^^^^^^^^^^^^^^^^^^^^^^^^^^^^^^^^^^^^^^^^^^^^^^^^
  File "/home/abdo/ITI/Ageri/venv/lib/python3.12/site-packages/django/db/models/query.py", line 1436, in filter
    return self._filter_or_exclude(False, args, kwargs)
           ^^^^^^^^^^^^^^^^^^^^^^^^^^^^^^^^^^^^^^^^^^^^
  File "/home/abdo/ITI/Ageri/venv/lib/python3.12/site-packages/django/db/models/query.py", line 1454, in _filter_or_exclude
    clone._filter_or_exclude_inplace(negate, args, kwargs)
  File "/home/abdo/ITI/Ageri/venv/lib/python3.12/site-packages/django/db/models/query.py", line 1461, in _filter_or_exclude_inplace
    self._query.add_q(Q(*args, **kwargs))
  File "/home/abdo/ITI/Ageri/venv/lib/python3.12/site-packages/django/db/models/sql/query.py", line 1545, in add_q
    clause, _ = self._add_q(q_object, self.used_aliases)
                ^^^^^^^^^^^^^^^^^^^^^^^^^^^^^^^^^^^^^^^^
  File "/home/abdo/ITI/Ageri/venv/lib/python3.12/site-packages/django/db/models/sql/query.py", line 1576, in _add_q
    child_clause, needed_inner = self.build_filter(
                                 ^^^^^^^^^^^^^^^^^^
  File "/home/abdo/ITI/Ageri/venv/lib/python3.12/site-packages/django/db/models/sql/query.py", line 1426, in build_filter
    lookups, parts, reffed_expression = self.solve_lookup_type(arg, summarize)
                                        ^^^^^^^^^^^^^^^^^^^^^^^^^^^^^^^^^^^^^^
  File "/home/abdo/ITI/Ageri/venv/lib/python3.12/site-packages/django/db/models/sql/query.py", line 1236, in solve_lookup_type
    _, field, _, lookup_parts = self.names_to_path(lookup_splitted, self.get_meta())
                                ^^^^^^^^^^^^^^^^^^^^^^^^^^^^^^^^^^^^^^^^^^^^^^^^^^^^
  File "/home/abdo/ITI/Ageri/venv/lib/python3.12/site-packages/django/db/models/sql/query.py", line 1724, in names_to_path
    raise FieldError(
django.core.exceptions.FieldError: Cannot resolve keyword 'status' into field. Choices are: approval_date, approved_announcements, approved_by, approved_by_id, approved_comments, approved_posts, approved_users, assigned_requests, assigned_service_requests, assigned_services, authored_announcements, authored_posts, comment_likes, comments, coordinated_public_services, corresponding_publications, course_enrollments, date_joined, department, departments, email, first_name, groups, headed_departments, headed_labs, id, institution, is_active, is_approved, is_staff, is_superuser, lab_assignments, labs, last_login, last_name, logentry, made_assignments, password, phone, profile, publication_assignments, publications, reviewed_publications, reviewed_service_requests, reviewed_summer_applications, role, service_assignments, service_requests, submitted_publications, summer_training_applications, supervised_summer_trainings, taught_courses, user_permissions, username
WARNING 2025-07-08 13:10:38,412 log 31013 131555038400640 Forbidden: /api/services/requests/1/approve_request/
WARNING 2025-07-08 13:10:39,652 log 31013 131555038400640 Bad Request: /api/services/requests/1/assign_technician/
WARNING 2025-07-08 13:10:40,801 log 31013 131555038400640 Forbidden: /api/services/clients/
WARNING 2025-07-08 13:10:44,418 log 31013 131555038400640 Forbidden: /api/services/test-services/
WARNING 2025-07-08 13:10:53,593 log 31013 131555038400640 Forbidden: /api/training/api/courses/
WARNING 2025-07-08 13:10:56,994 log 31013 131555038400640 Unauthorized: /api/training/api/courses/
WARNING 2025-07-08 13:10:57,764 log 31013 131555038400640 Bad Request: /api/training/api/courses/1/enroll/
INFO 2025-07-08 13:43:03,846 autoreload 36599 130323094945920 Watching for file changes with StatReloader
INFO 2025-07-08 14:04:30,084 basehttp 36599 130323017889472 "GET /api/docs/ HTTP/1.1" 200 4487
WARNING 2025-07-08 14:27:30,860 log 42593 132562976796800 Forbidden: /api/organization/departments/
WARNING 2025-07-08 14:27:33,423 log 42593 132562976796800 Unauthorized: /api/organization/departments/
WARNING 2025-07-08 14:30:12,489 log 43200 127580730900608 Forbidden: /api/organization/departments/
WARNING 2025-07-08 14:30:15,370 log 43200 127580730900608 Unauthorized: /api/organization/departments/
WARNING 2025-07-08 14:37:49,021 log 43997 138419378053248 Forbidden: /api/organization/departments/
WARNING 2025-07-08 14:37:51,212 log 43997 138419378053248 Unauthorized: /api/organization/departments/
WARNING 2025-07-08 14:56:25,078 log 45645 125651787821184 Bad Request: /api/auth/users/me/
WARNING 2025-07-08 14:56:26,188 log 45645 125651787821184 Forbidden: /api/auth/users/3/approve/
WARNING 2025-07-08 14:56:26,189 log 45645 125651787821184 Method Not Allowed: /api/auth/users/3/approve/
WARNING 2025-07-08 14:56:28,665 log 45645 125651787821184 Bad Request: /api/auth/login/
WARNING 2025-07-08 14:56:30,130 log 45645 125651787821184 Bad Request: /api/auth/login/
WARNING 2025-07-08 14:56:30,872 log 45645 125651787821184 Bad Request: /api/auth/register/
WARNING 2025-07-08 14:56:32,017 log 45645 125651787821184 Bad Request: /api/auth/register/
WARNING 2025-07-08 14:56:33,283 log 45645 125651787821184 Forbidden: /api/auth/users/
WARNING 2025-07-08 14:56:52,444 log 45645 125651787821184 Forbidden: /api/organization/departments/
WARNING 2025-07-08 14:56:55,343 log 45645 125651787821184 Unauthorized: /api/organization/departments/
WARNING 2025-07-08 14:57:06,058 log 45645 125651787821184 Forbidden: /api/services/requests/1/approve_request/
WARNING 2025-07-08 14:57:07,327 log 45645 125651787821184 Bad Request: /api/services/requests/1/assign_technician/
WARNING 2025-07-08 14:57:08,468 log 45645 125651787821184 Forbidden: /api/services/clients/
WARNING 2025-07-08 14:57:12,905 log 45645 125651787821184 Forbidden: /api/services/test-services/
WARNING 2025-07-08 14:57:22,515 log 45645 125651787821184 Forbidden: /api/training/api/courses/
WARNING 2025-07-08 14:57:25,823 log 45645 125651787821184 Unauthorized: /api/training/api/courses/
WARNING 2025-07-08 14:57:26,685 log 45645 125651787821184 Bad Request: /api/training/api/courses/1/enroll/
WARNING 2025-07-08 15:37:43,659 log 11067 127707330330752 Bad Request: /api/auth/users/me/
WARNING 2025-07-08 15:37:48,390 log 11067 127707330330752 Forbidden: /api/auth/users/3/approve/
WARNING 2025-07-08 15:37:56,873 log 11067 127707330330752 Bad Request: /api/auth/login/
WARNING 2025-07-08 15:38:02,532 log 11067 127707330330752 Bad Request: /api/auth/login/
WARNING 2025-07-08 15:38:11,181 log 11067 127707330330752 Bad Request: /api/auth/register/
WARNING 2025-07-08 15:38:16,196 log 11067 127707330330752 Forbidden: /api/auth/users/
WARNING 2025-07-08 15:47:03,828 log 12439 131468635353216 Bad Request: /api/auth/users/me/
WARNING 2025-07-08 15:47:08,425 log 12439 131468635353216 Forbidden: /api/auth/users/3/approve/
WARNING 2025-07-08 15:47:17,813 log 12439 131468635353216 Bad Request: /api/auth/login/
WARNING 2025-07-08 15:47:23,462 log 12439 131468635353216 Bad Request: /api/auth/login/
WARNING 2025-07-08 15:47:32,179 log 12439 131468635353216 Bad Request: /api/auth/register/
WARNING 2025-07-08 15:47:36,496 log 12439 131468635353216 Forbidden: /api/auth/users/
WARNING 2025-07-08 15:48:43,904 log 12439 131468635353216 Forbidden: /api/organization/departments/
WARNING 2025-07-08 15:48:53,826 log 12439 131468635353216 Unauthorized: /api/organization/departments/
WARNING 2025-07-08 15:49:26,175 log 12439 131468635353216 Forbidden: /api/services/requests/1/approve_request/
WARNING 2025-07-08 15:49:30,781 log 12439 131468635353216 Bad Request: /api/services/requests/1/assign_technician/
WARNING 2025-07-08 15:49:34,932 log 12439 131468635353216 Forbidden: /api/services/clients/
WARNING 2025-07-08 15:49:46,820 log 12439 131468635353216 Forbidden: /api/services/test-services/
WARNING 2025-07-08 16:05:43,913 log 15865 139729272303744 Bad Request: /api/auth/users/me/
WARNING 2025-07-08 16:05:48,784 log 15865 139729272303744 Forbidden: /api/auth/users/3/approve/
WARNING 2025-07-08 16:05:58,718 log 15865 139729272303744 Bad Request: /api/auth/login/
WARNING 2025-07-08 16:06:05,554 log 15865 139729272303744 Bad Request: /api/auth/login/
WARNING 2025-07-08 16:06:15,496 log 15865 139729272303744 Bad Request: /api/auth/register/
WARNING 2025-07-08 16:06:20,756 log 15865 139729272303744 Forbidden: /api/auth/users/
WARNING 2025-07-08 16:07:51,378 log 15865 139729272303744 Forbidden: /api/organization/departments/
WARNING 2025-07-08 16:08:01,227 log 15865 139729272303744 Unauthorized: /api/organization/departments/
WARNING 2025-07-08 16:08:36,275 log 15865 139729272303744 Forbidden: /api/services/requests/1/approve_request/
WARNING 2025-07-08 16:08:43,199 log 15865 139729272303744 Bad Request: /api/services/requests/1/assign_technician/
WARNING 2025-07-08 16:08:49,833 log 15865 139729272303744 Forbidden: /api/services/clients/
WARNING 2025-07-08 16:09:08,857 log 15865 139729272303744 Forbidden: /api/services/test-services/
WARNING 2025-07-08 16:09:54,133 log 15865 139729272303744 Forbidden: /api/training/api/courses/
WARNING 2025-07-08 16:10:12,701 log 15865 139729272303744 Unauthorized: /api/training/api/courses/
WARNING 2025-07-08 16:10:17,009 log 15865 139729272303744 Bad Request: /api/training/api/courses/1/enroll/
WARNING 2025-07-08 16:55:11,582 log 23330 124112949756032 Bad Request: /api/auth/users/me/
WARNING 2025-07-08 16:55:16,412 log 23330 124112949756032 Forbidden: /api/auth/users/3/approve/
WARNING 2025-07-08 16:55:25,571 log 23330 124112949756032 Bad Request: /api/auth/login/
WARNING 2025-07-08 16:55:32,329 log 23330 124112949756032 Bad Request: /api/auth/login/
WARNING 2025-07-08 16:55:42,389 log 23330 124112949756032 Bad Request: /api/auth/register/
WARNING 2025-07-08 16:55:47,199 log 23330 124112949756032 Forbidden: /api/auth/users/
WARNING 2025-07-08 16:57:04,653 log 23330 124112949756032 Forbidden: /api/organization/departments/
WARNING 2025-07-08 16:57:14,774 log 23330 124112949756032 Unauthorized: /api/organization/departments/
WARNING 2025-07-08 16:57:43,614 log 23330 124112949756032 Forbidden: /api/services/requests/1/approve_request/
WARNING 2025-07-08 16:57:48,626 log 23330 124112949756032 Bad Request: /api/services/requests/1/assign_technician/
WARNING 2025-07-08 16:57:53,153 log 23330 124112949756032 Forbidden: /api/services/clients/
WARNING 2025-07-08 16:58:07,137 log 23330 124112949756032 Forbidden: /api/services/test-services/
WARNING 2025-07-08 16:58:32,787 log 23330 124112949756032 Unauthorized: /api/services/test-services/
WARNING 2025-07-08 16:58:39,623 log 23330 124112949756032 Forbidden: /api/training/api/courses/
WARNING 2025-07-08 16:58:54,694 log 23330 124112949756032 Unauthorized: /api/training/api/courses/
WARNING 2025-07-08 16:58:58,360 log 23330 124112949756032 Bad Request: /api/training/api/courses/1/enroll/
WARNING 2025-07-08 17:01:19,142 log 24828 137839685886080 Bad Request: /api/auth/users/me/
WARNING 2025-07-08 17:07:54,487 log 25882 124330741932160 Bad Request: /api/services/requests/1/assign_technician/
WARNING 2025-07-08 17:45:43,845 log 30039 132109404921984 Forbidden: /api/auth/users/3/approve/
WARNING 2025-07-08 17:45:56,613 log 30039 132109404921984 Bad Request: /api/auth/login/
WARNING 2025-07-08 17:46:05,046 log 30039 132109404921984 Bad Request: /api/auth/login/
WARNING 2025-07-08 17:46:18,364 log 30039 132109404921984 Bad Request: /api/auth/register/
WARNING 2025-07-08 17:46:24,185 log 30039 132109404921984 Forbidden: /api/auth/users/
WARNING 2025-07-08 17:47:47,263 log 30039 132109404921984 Forbidden: /api/organization/departments/
WARNING 2025-07-08 17:47:59,652 log 30039 132109404921984 Unauthorized: /api/organization/departments/
WARNING 2025-07-08 17:48:40,821 log 30039 132109404921984 Forbidden: /api/services/requests/1/approve_request/
WARNING 2025-07-08 17:48:52,903 log 30039 132109404921984 Forbidden: /api/services/clients/
WARNING 2025-07-08 17:49:11,570 log 30039 132109404921984 Forbidden: /api/services/test-services/
WARNING 2025-07-08 17:49:40,593 log 30039 132109404921984 Unauthorized: /api/services/test-services/
WARNING 2025-07-08 17:49:47,408 log 30039 132109404921984 Forbidden: /api/training/api/courses/
WARNING 2025-07-08 17:49:59,610 log 30039 132109404921984 Unauthorized: /api/training/api/courses/
WARNING 2025-07-08 17:50:02,354 log 30039 132109404921984 Bad Request: /api/training/api/courses/1/enroll/
